[NbConvertApp] Converting notebook /tmp/input.ipynb to notebook
[NbConvertApp] Executing notebook with kernel: python
[NbConvertApp] ERROR | Error while converting '/tmp/input.ipynb'
Traceback (most recent call last):
  File "/opt/conda/lib/python3.7/site-packages/nbconvert/nbconvertapp.py", line 407, in export_single_notebook
    output, resources = self.exporter.from_filename(notebook_filename, resources=resources)
  File "/opt/conda/lib/python3.7/site-packages/nbconvert/exporters/exporter.py", line 178, in from_filename
    return self.from_file(f, resources=resources, **kw)
  File "/opt/conda/lib/python3.7/site-packages/nbconvert/exporters/exporter.py", line 196, in from_file
    return self.from_notebook_node(nbformat.read(file_stream, as_version=4), resources=resources, **kw)
  File "/opt/conda/lib/python3.7/site-packages/nbconvert/exporters/notebook.py", line 32, in from_notebook_node
    nb_copy, resources = super(NotebookExporter, self).from_notebook_node(nb, resources, **kw)
  File "/opt/conda/lib/python3.7/site-packages/nbconvert/exporters/exporter.py", line 138, in from_notebook_node
    nb_copy, resources = self._preprocess(nb_copy, resources)
  File "/opt/conda/lib/python3.7/site-packages/nbconvert/exporters/exporter.py", line 315, in _preprocess
    nbc, resc = preprocessor(nbc, resc)
  File "/opt/conda/lib/python3.7/site-packages/nbconvert/preprocessors/base.py", line 47, in __call__
    return self.preprocess(nb, resources)
  File "/opt/conda/lib/python3.7/site-packages/nbconvert/preprocessors/execute.py", line 354, in preprocess
    nb, resources = super(ExecutePreprocessor, self).preprocess(nb, resources)
  File "/opt/conda/lib/python3.7/site-packages/nbconvert/preprocessors/base.py", line 69, in preprocess
    nb.cells[index], resources = self.preprocess_cell(cell, resources, index)
  File "/opt/conda/lib/python3.7/site-packages/nbconvert/preprocessors/execute.py", line 378, in preprocess_cell
    raise CellExecutionError.from_cell_and_msg(cell, out)
nbconvert.preprocessors.execute.CellExecutionError: An error occurred while executing the following cell:
------------------
import pandas as pd

study_info = {'study_id': [1 , 1],
        'study_info': ["Charmin Forever Roll(FR2)", "Charmin Forever Roll(FR2)"],
        'Study_start_date': ['09-23-2019', '09-23-2019'],
        'Study_end_date': ['11-23-2020', '11-23-2020'],
        'country': ['USA', 'USA'],
        'market': ['CHICAGO','DALLAS'],
        'market_code' : [1000,2000],
        'Roll_start': ['1', '1'],
        'Roll_end': ['19100', '19100']}

study_info_df = pd.DataFrame(study_info)

study_info_df.to_csv(os.path.join(
            os.environ['OUTPUT_DIR'], "study_info.csv"), index=False)
------------------

---------------------------------------------------------------------------
NameError                                 Traceback (most recent call last)
<ipython-input-1-9afb533c420c> in <module>
     13 study_info_df = pd.DataFrame(study_info)
     14 
---> 15 study_info_df.to_csv(os.path.join(
     16             os.environ['OUTPUT_DIR'], "study_info.csv"), index=False)

NameError: name 'os' is not defined
NameError: name 'os' is not defined


Jupyter exited with status code: 1
